{"assignees":[{"id":"MDQ6VXNlcjExNjY0MjU5","login":"galipremsagar","name":"GALI PREM SAGAR"}],"author":{"id":"MDQ6VXNlcjExMjY1Mw==","is_bot":false,"login":"mattf","name":"Matthew Farrellee"},"body":"**Describe the bug**\r\nrewriting code from pandas to cudf, using `import cudf as pd`\r\n\r\n**Steps/Code to reproduce bug**\r\n\r\n```\r\n$ python\r\nPython 3.9.13 (main, May 18 2022, 00:00:00) \r\n[GCC 11.3.1 20220421 (Red Hat 11.3.1-2)] on linux\r\nType \"help\", \"copyright\", \"credits\" or \"license\" for more information.\r\n>>> import pandas, cudf\r\n\r\n>>> pandas.__version__\r\n'1.5.1'\r\n\r\n>>> cudf.__version__\r\n'22.10.00a+392.g1558403753'\r\n\r\n>>> pandas.Series([1, None], dtype=\"Int64\")\r\n0       1\r\n1    <NA>\r\ndtype: Int64\r\n\r\n>>> pandas.Series([1, None], dtype=\"int64\")\r\nTraceback (most recent call last):\r\n  File \"<stdin>\", line 1, in <module>\r\n  File \".../python3.9/site-packages/pandas/core/series.py\", line 470, in __init__\r\n    data = sanitize_array(data, index, dtype, copy)\r\n  File \".../python3.9/site-packages/pandas/core/construction.py\", line 622, in sanitize_array\r\n    subarr = _try_cast(data, dtype, copy, raise_cast_failure)\r\n  File \".../python3.9/site-packages/pandas/core/construction.py\", line 835, in _try_cast\r\n    subarr = maybe_cast_to_integer_array(arr, dtype)\r\n  File \".../python3.9/site-packages/pandas/core/dtypes/cast.py\", line 1834, in maybe_cast_to_integer_array\r\n    casted = np.array(arr, dtype=dtype, copy=copy)\r\nTypeError: int() argument must be a string, a bytes-like object or a number, not 'NoneType'\r\n\r\n>>> cudf.Series([1, None], dtype=\"Int64\")\r\nTraceback (most recent call last):\r\n  File \".../python3.9/site-packages/cudf/core/column/column.py\", line 2038, in as_column\r\n    memoryview(arbitrary), dtype=dtype, nan_as_null=nan_as_null\r\nTypeError: memoryview: a bytes-like object is required, not 'list'\r\nDuring handling of the above exception, another exception occurred:\r\nTraceback (most recent call last):\r\n  File \".../python3.9/site-packages/cudf/core/column/column.py\", line 2127, in as_column\r\n    np_type = np.dtype(dtype).type\r\nTypeError: data type 'Int64' not understood\r\nDuring handling of the above exception, another exception occurred:\r\nTraceback (most recent call last):\r\n  File \".../python3.9/site-packages/cudf/core/column/column.py\", line 2199, in _construct_array\r\n    arbitrary = cupy.asarray(arbitrary, dtype=dtype)\r\n  File \".../python3.9/site-packages/cupy/_creation/from_data.py\", line 76, in asarray\r\n    return _core.array(a, dtype, False, order)\r\n  File \"cupy/_core/core.pyx\", line 2266, in cupy._core.core.array\r\n  File \"cupy/_core/core.pyx\", line 2290, in cupy._core.core.array\r\n  File \"cupy/_core/core.pyx\", line 2415, in cupy._core.core._array_default\r\nTypeError: int() argument must be a string, a bytes-like object or a number, not 'NoneType'\r\nDuring handling of the above exception, another exception occurred:\r\nTraceback (most recent call last):\r\n  File \"<stdin>\", line 1, in <module>\r\n  File \".../python3.9/site-packages/nvtx/nvtx.py\", line 101, in inner\r\n    result = func(*args, **kwargs)\r\n  File \".../python3.9/site-packages/cudf/core/series.py\", line 536, in __init__\r\n    data = column.as_column(data, nan_as_null=nan_as_null, dtype=dtype)\r\n  File \".../python3.9/site-packages/cudf/core/column/column.py\", line 2184, in as_column\r\n    _construct_array(arbitrary, dtype),\r\n  File \".../python3.9/site-packages/cudf/core/column/column.py\", line 2212, in _construct_array\r\n    arbitrary = np.asarray(\r\nTypeError: int() argument must be a string, a bytes-like object or a number, not 'NoneType'\r\n\r\n>>> cudf.Series([1, None], dtype=\"int64\")\r\n0       1\r\n1    <NA>\r\ndtype: int64\r\n\r\n```\r\n\r\n\r\n\r\n**Expected behavior**\r\nmatching behavior for `Int64` and `int64`\r\n\r\nref https://pandas.pydata.org/pandas-docs/stable/user_guide/integer_na.html and https://pandas.pydata.org/docs/user_guide/basics.html#basics-dtypes","closed":false,"closedAt":null,"comments":[],"createdAt":"2022-10-24T11:25:25Z","id":"I_kwDOBWUGps5Urcun","labels":[{"id":"MDU6TGFiZWw1OTk2MjY1NTk=","name":"bug","description":"Something isn't working","color":"d73a4a"},{"id":"MDU6TGFiZWwxMTM5NzQxMjEz","name":"cuDF (Python)","description":"Affects Python cuDF API.","color":"1d76db"}],"milestone":{"number":5,"title":"Pandas API Alignment and Coverage","description":"","dueOn":null},"number":11976,"projectCards":[{"project":{"name":"Bug Squashing"},"column":{"name":"Needs prioritizing"}}],"projectItems":[],"reactionGroups":[],"state":"OPEN","title":"[BUG] semantic mismatch for Int64 and int64","updatedAt":"2023-02-09T17:01:23Z","url":"https://github.com/rapidsai/cudf/issues/11976"}
